// Error handling utilities
export class AppError extends Error {
  constructor(
    public code: string,
    message: string,
    public statusCode: number = 500,
    public details?: Record<string, any>
  ) {
    super(message);
    this.name = 'AppError';
  }
}

export class ValidationError extends AppError {
  constructor(message: string, details?: Record<string, any>) {
    super('VALIDATION_ERROR', message, 400, details);
    this.name = 'ValidationError';
  }
}

export class AuthenticationError extends AppError {
  constructor(message: string = 'Authentication failed') {
    super('AUTH_ERROR', message, 401);
    this.name = 'AuthenticationError';
  }
}

export class AuthorizationError extends AppError {
  constructor(message: string = 'You do not have permission to perform this action') {
    super('AUTHZ_ERROR', message, 403);
    this.name = 'AuthorizationError';
  }
}

export class NotFoundError extends AppError {
  constructor(message: string = 'Resource not found') {
    super('NOT_FOUND', message, 404);
    this.name = 'NotFoundError';
  }
}

export class ConflictError extends AppError {
  constructor(message: string = 'Resource already exists') {
    super('CONFLICT', message, 409);
    this.name = 'ConflictError';
  }
}

// Error handling utilities
export const isAppError = (error: unknown): error is AppError => {
  return error instanceof AppError;
};

export const getErrorMessage = (error: unknown): string => {
  if (error instanceof AppError) {
    return error.message;
  }
  if (error instanceof Error) {
    return error.message;
  }
  return 'An unexpected error occurred';
};

export const handleError = (error: unknown): AppError => {
  if (error instanceof AppError) {
    return error;
  }

  if (error instanceof Error) {
    return new AppError('UNKNOWN_ERROR', error.message);
  }

  return new AppError('UNKNOWN_ERROR', 'An unexpected error occurred');
};
